<sdf version='1.6'>
  <model name='h_frame_tilt'>
    <link name='base_link'>
      <pose frame=''>0 0 0 0 -0 0</pose>
      <inertial>
        <pose frame=''>-0.008889 0 1.8e-05 0 -0 0</pose>
        <mass>1.31847</mass>
        <inertia>
          <ixx>0.114109</ixx>
          <ixy>-6.09508e-15</ixy>
          <ixz>2.32413e-06</ixz>
          <iyy>0.0633109</iyy>
          <iyz>-1.95647e-13</iyz>
          <izz>0.177329</izz>
        </inertia>
      </inertial>
      <collision name='base_link_collision'>
        <pose frame=''>0 0 0 0 -0 0</pose>
        <geometry>
          <mesh>
            <scale>1 1 1</scale>
            <uri>model://h_frame_tilt/meshes/base_link.STL</uri>
          </mesh>
        </geometry>
      </collision>
      <collision name='base_link_fixed_joint_lump__motor_0_collision_1'>
        <pose frame=''>0.43 -0.3 0.005 0 -0 0</pose>
        <geometry>
          <mesh>
            <scale>1 1 1</scale>
            <uri>model://h_frame_tilt/meshes/motor_0.STL</uri>
          </mesh>
        </geometry>
      </collision>
      <collision name='base_link_fixed_joint_lump__motor_2_collision_2'>
        <pose frame=''>0.43 0.3 0.005 0 -0 0</pose>
        <geometry>
          <mesh>
            <scale>1 1 1</scale>
            <uri>model://h_frame_tilt/meshes/motor_2.STL</uri>
          </mesh>
        </geometry>
      </collision>
      <visual name='base_link_visual'>
        <pose frame=''>0 0 0 0 -0 0</pose>
        <geometry>
          <mesh>
            <scale>1 1 1</scale>
            <uri>model://h_frame_tilt/meshes/base_link.STL</uri>
          </mesh>
        </geometry>
      </visual>
      <visual name='base_link_fixed_joint_lump__motor_0_visual_1'>
        <pose frame=''>0.43 -0.3 0.005 0 -0 0</pose>
        <geometry>
          <mesh>
            <scale>1 1 1</scale>
            <uri>model://h_frame_tilt/meshes/motor_0.STL</uri>
          </mesh>
        </geometry>
      </visual>
      <visual name='base_link_fixed_joint_lump__motor_2_visual_2'>
        <pose frame=''>0.43 0.3 0.005 0 -0 0</pose>
        <geometry>
          <mesh>
            <scale>1 1 1</scale>
            <uri>model://h_frame_tilt/meshes/motor_2.STL</uri>
          </mesh>
        </geometry>
      </visual>
    </link>
    <link name='h_frame_tilt/imu_link'>
      <inertial>
        <pose>0 0 0 0 0 0</pose>
        <mass>0.15</mass>
        <inertia>
          <ixx>0.00001</ixx>
          <ixy>0</ixy>
          <ixz>0</ixz>
          <iyy>0.00002</iyy>
          <iyz>0</iyz>
          <izz>0.00002</izz>
        </inertia>
      </inertial>
      <sensor name="imu_sensor" type="imu">
        <pose>0 0 0 3.141593 0 0</pose>
        <always_on>1</always_on>
        <update_rate>1000.0</update_rate>
      </sensor>
    </link>
    <joint name='h_frame_tilt/imu_joint' type='revolute'>
      <child>h_frame_tilt/imu_link</child>
      <parent>base_link</parent>
      <axis>
        <xyz>0 0 1</xyz>
        <limit>
          <lower>0</lower>
          <upper>0</upper>
          <effort>0</effort>
          <velocity>0</velocity>
        </limit>
        <dynamics>
          <damping>1.0</damping>
        </dynamics>
        <use_parent_model_frame>1</use_parent_model_frame>
      </axis>
      <physics>
        <ode>
          <implicit_spring_damper>1</implicit_spring_damper>
        </ode>
      </physics>
    </joint>
    <link name='rotor_0'>
      <pose frame=''>0.43 -0.325 0.026 0 -0 0</pose>
      <inertial>
        <pose frame=''>0 0 -0.00744 0 -0 0</pose>
        <mass>0.067291</mass>
        <inertia>
          <ixx>0.0014412</ixx>
          <ixy>-7.5965e-05</ixy>
          <ixz>-8.781e-13</ixz>
          <iyy>1.2633e-05</iyy>
          <iyz>-3.4466e-12</iyz>
          <izz>0.0014525</izz>
        </inertia>
      </inertial>
      <collision name='rotor_0_collision'>
        <pose frame=''>0 0 0 0 -0 0</pose>
        <geometry>
          <mesh>
            <scale>1 1 1</scale>
            <uri>model://h_frame_tilt/meshes/rotor_0.STL</uri>
          </mesh>
        </geometry>
      </collision>
      <visual name='rotor_0_visual'>
        <pose frame=''>0 0 0 0 -0 0</pose>
        <geometry>
          <mesh>
            <scale>1 1 1</scale>
            <uri>model://h_frame_tilt/meshes/rotor_0.STL</uri>
          </mesh>
        </geometry>
      </visual>
    </link>
    <joint name='rotor_0_joint' type='revolute'>
      <child>rotor_0</child>
      <parent>base_link</parent>
      <axis>
        <xyz>0 0 1</xyz>
        <limit>
          <lower>-1e+16</lower>
          <upper>1e+16</upper>
        </limit>
        <dynamics>
          <damping>0.004</damping>
          <spring_reference>0</spring_reference>
          <spring_stiffness>0</spring_stiffness>
        </dynamics>
        <use_parent_model_frame>1</use_parent_model_frame>
      </axis>
      <physics>
          <ode>
            <implicit_spring_damper>1</implicit_spring_damper>
          </ode>
      </physics>
    </joint>
    <link name='rotor_2'>
      <pose frame=''>0.43 0.325 0.026 0 -0 0</pose>
      <inertial>
        <pose frame=''>0 0 -0.00744 0 -0 0</pose>
        <mass>0.067292</mass>
        <inertia>
          <ixx>0.0014451</ixx>
          <ixy>-1.3765e-05</ixy>
          <ixz>-1.154e-12</ixz>
          <iyy>8.7366e-06</iyy>
          <iyz>-9.362e-13</iyz>
          <izz>0.0014525</izz>
        </inertia>
      </inertial>
      <collision name='rotor_2_collision'>
        <pose frame=''>0 0 0 0 -0 0</pose>
        <geometry>
          <mesh>
            <scale>1 1 1</scale>
            <uri>model://h_frame_tilt/meshes/rotor_2.STL</uri>
          </mesh>
        </geometry>
      </collision>
      <visual name='rotor_2_visual'>
        <pose frame=''>0 0 0 0 -0 0</pose>
        <geometry>
          <mesh>
            <scale>1 1 1</scale>
            <uri>model://h_frame_tilt/meshes/rotor_2.STL</uri>
          </mesh>
        </geometry>
      </visual>
    </link>
    <joint name='rotor_2_joint' type='revolute'>
      <child>rotor_2</child>
      <parent>base_link</parent>
      <axis>
        <xyz>0 0 1</xyz>
        <limit>
          <lower>-1e+16</lower>
          <upper>1e+16</upper>
        </limit>
        <dynamics>
          <damping>0.004</damping>
          <spring_reference>0</spring_reference>
          <spring_stiffness>0</spring_stiffness>
        </dynamics>
        <use_parent_model_frame>1</use_parent_model_frame>
      </axis>
      <physics>
          <ode>
            <implicit_spring_damper>1</implicit_spring_damper>
          </ode>
      </physics>
    </joint>
    <link name='rotor_1'>
      <pose frame=''>-0.43 0.325 0.003413 0 -0 0</pose>
      <inertial>
        <pose frame=''>-0 0 0.015147 0 -0 0</pose>
        <mass>0.067291</mass>
        <inertia>
          <ixx>0.0014428</ixx>
          <ixy>5.9289e-05</ixy>
          <ixz>1.6714e-12</ixz>
          <iyy>1.1056e-05</iyy>
          <iyz>-1.5765e-12</iyz>
          <izz>0.0014525</izz>
        </inertia>
      </inertial>
      <collision name='rotor_1_collision'>
        <pose frame=''>0 0 0 0 -0 0</pose>
        <geometry>
          <mesh>
            <scale>1 1 1</scale>
            <uri>model://h_frame_tilt/meshes/rotor_1.STL</uri>
          </mesh>
        </geometry>
      </collision>
      <visual name='rotor_1_visual'>
        <pose frame=''>0 0 0 0 -0 0</pose>
        <geometry>
          <mesh>
            <scale>1 1 1</scale>
            <uri>model://h_frame_tilt/meshes/rotor_1.STL</uri>
          </mesh>
        </geometry>
      </visual>
    </link>
    <joint name='rotor_1_joint' type='revolute'>
      <child>rotor_1</child>
      <parent>base_link</parent>
      <axis>
        <xyz>0 0 1</xyz>
        <limit>
          <lower>-1e+16</lower>
          <upper>1e+16</upper>
        </limit>
        <dynamics>
          <damping>0.004</damping>
          <spring_reference>0</spring_reference>
          <spring_stiffness>0</spring_stiffness>
        </dynamics>
        <use_parent_model_frame>1</use_parent_model_frame>
      </axis>
      <physics>
          <ode>
            <implicit_spring_damper>1</implicit_spring_damper>
          </ode>
      </physics>
    </joint>
    <link name='rotor_3'>
      <pose frame=''>-0.43 -0.325 0.003413 0 -0 0</pose>
      <inertial>
        <pose frame=''>0 -0 0.015147 0 -0 0</pose>
        <mass>0.067296</mass>
        <inertia>
          <ixx>0.0014418</ixx>
          <ixy>-7.2037e-05</ixy>
          <ixz>-1.1454e-12</ixz>
          <iyy>1.2226e-05</iyy>
          <iyz>1.0716e-12</iyz>
          <izz>0.0014526</izz>
        </inertia>
      </inertial>
      <collision name='rotor_3_collision'>
        <pose frame=''>0 0 0 0 -0 0</pose>
        <geometry>
          <mesh>
            <scale>1 1 1</scale>
            <uri>model://h_frame_tilt/meshes/rotor_3.STL</uri>
          </mesh>
        </geometry>
      </collision>
      <visual name='rotor_3_visual'>
        <pose frame=''>0 0 0 0 -0 0</pose>
        <geometry>
          <mesh>
            <scale>1 1 1</scale>
            <uri>model://h_frame_tilt/meshes/rotor_3.STL</uri>
          </mesh>
        </geometry>
      </visual>
    </link>
    <joint name='rotor_3_joint' type='revolute'>
      <child>rotor_3</child>
      <parent>base_link</parent>
      <axis>
        <xyz>0 0 1</xyz>
        <limit>
          <lower>-1e+16</lower>
          <upper>1e+16</upper>
        </limit>
        <dynamics>
          <damping>0.004</damping>
          <spring_reference>0</spring_reference>
          <spring_stiffness>0</spring_stiffness>
        </dynamics>
        <use_parent_model_frame>1</use_parent_model_frame>
      </axis>
      <physics>
          <ode>
            <implicit_spring_damper>1</implicit_spring_damper>
          </ode>
      </physics>
    </joint>

  <plugin name="rotor_0_blade_1" filename="libLiftDragPlugin.so">
      <a0>0.3</a0>
      <alpha_stall>1.4</alpha_stall>
      <cla>4.2500</cla>
      <cda>0.10</cda>
      <cma>0.00</cma>
      <cla_stall>-0.025</cla_stall>
      <cda_stall>0.0</cda_stall>
      <cma_stall>0.0</cma_stall>
      <area>0.01</area>
      <air_density>1.2041</air_density>
      <cp>0  0.093 0</cp>
      <forward>-1 0 0</forward>
      <upward>0 0 1</upward>
      <link_name>rotor_0</link_name>
    </plugin>
    <plugin name="rotor_0_blade_2" filename="libLiftDragPlugin.so">
      <a0>0.3</a0>
      <alpha_stall>1.4</alpha_stall>
      <cla>4.2500</cla>
      <cda>0.10</cda>
      <cma>0.00</cma>
      <cla_stall>-0.025</cla_stall>
      <cda_stall>0.0</cda_stall>
      <cma_stall>0.0</cma_stall>
      <area>0.01</area>
      <air_density>1.2041</air_density>
       <cp>0 -0.093 0</cp>
      <forward>1 0 0</forward>
      <upward>0 0 1</upward>
      <link_name>rotor_0</link_name>
    </plugin>
 <plugin name="rotor_1_blade_1" filename="libLiftDragPlugin.so">
      <a0>0.3</a0>
      <alpha_stall>1.4</alpha_stall>
      <cla>4.2500</cla>
      <cda>0.10</cda>
      <cma>0.00</cma>
      <cla_stall>-0.025</cla_stall>
      <cda_stall>0.0</cda_stall>
      <cma_stall>0.0</cma_stall>
      <area>0.01</area>
      <air_density>1.2041</air_density>
       <cp>0 0.093 0</cp>
      <forward>-1 0 0</forward>
      <upward>0 0 1</upward>
      <link_name>rotor_1</link_name>
    </plugin>
    <plugin name="rotor_1_blade_2" filename="libLiftDragPlugin.so">
      <a0>0.3</a0>
      <alpha_stall>1.4</alpha_stall>
      <cla>4.2500</cla>
      <cda>0.10</cda>
      <cma>0.00</cma>
      <cla_stall>-0.025</cla_stall>
      <cda_stall>0.0</cda_stall>
      <cma_stall>0.0</cma_stall>
      <area>0.01</area>
      <air_density>1.2041</air_density>
      <cp>0  -0.093 0</cp>
      <forward>1 0 0</forward>
      <upward>0 0 1</upward>
      <link_name>rotor_1</link_name>
    </plugin>
<plugin name="rotor_2_blade_1" filename="libLiftDragPlugin.so">
      <a0>0.3</a0>
      <alpha_stall>1.4</alpha_stall>
      <cla>4.2500</cla>
      <cda>0.10</cda>
      <cma>0.00</cma>
      <cla_stall>-0.025</cla_stall>
      <cda_stall>0.0</cda_stall>
      <cma_stall>0.0</cma_stall>
      <area>0.01</area>
      <air_density>1.2041</air_density>
      <cp>0  0.093 0</cp> 
      <forward>1 0 0</forward>
      <upward>0 0 1</upward>
      <link_name>rotor_2</link_name>
    </plugin>
    <plugin name="rotor_2_blade_2" filename="libLiftDragPlugin.so">
      <a0>0.3</a0>
      <alpha_stall>1.4</alpha_stall>
      <cla>4.2500</cla>
      <cda>0.10</cda>
      <cma>0.00</cma>
      <cla_stall>-0.025</cla_stall>
      <cda_stall>0.0</cda_stall>
      <cma_stall>0.0</cma_stall>
      <area>0.01</area>
      <air_density>1.2041</air_density>
       <cp>0 -0.093 0</cp>
      <forward>-1 0 0</forward>
      <upward>0 0 1</upward>
      <link_name>rotor_2</link_name>
    </plugin>
<plugin name="rotor_3_blade_1" filename="libLiftDragPlugin.so">
      <a0>0.3</a0>
      <alpha_stall>1.4</alpha_stall>
      <cla>4.2500</cla>
      <cda>0.10</cda>
      <cma>0.00</cma>
      <cla_stall>-0.025</cla_stall>
      <cda_stall>0.0</cda_stall>
      <cma_stall>0.0</cma_stall>
      <area>0.01</area>
      <air_density>1.2041</air_density>
      <cp>0  0.093 0</cp>
      <forward>1 0 0</forward>
      <upward>0 0 1</upward>
      <link_name>rotor_3</link_name>
    </plugin>
    <plugin name="rotor_3_blade_2" filename="libLiftDragPlugin.so">
      <a0>0.3</a0>
      <alpha_stall>1.4</alpha_stall>
      <cla>4.2500</cla>
      <cda>0.10</cda>
      <cma>0.00</cma>
      <cla_stall>-0.025</cla_stall>
      <cda_stall>0.0</cda_stall>
      <cma_stall>0.0</cma_stall>
      <area>0.01</area>
      <air_density>1.2041</air_density>
       <cp>0 -0.093 0</cp>
      <forward>-1 0 0</forward>
      <upward>0 0 1</upward>
      <link_name>rotor_3</link_name>
    </plugin>
 <plugin name="arducopter_plugin" filename="libArduPilotPlugin.so">
      <fdm_addr>127.0.0.1</fdm_addr>
      <fdm_port_in>9002</fdm_port_in>
      <fdm_port_out>9003</fdm_port_out>
      <!--
          Require by APM :
          Only change model and gazebo from XYZ to XY-Z coordinates
      -->
      <modelXYZToAirplaneXForwardZDown>0 0 0 3.141593 0 0</modelXYZToAirplaneXForwardZDown>
      <gazeboXYZToNED>0 0 0 3.141593 0 0</gazeboXYZToNED>
      <imuName>h_frame_tilt/imu_link::imu_sensor</imuName>
      <connectionTimeoutMaxCount>5</connectionTimeoutMaxCount>
      <!-- <control channel="2">
        
        <multiplier>-2000</multiplier>
        <offset>0.2</offset>
        <type>VELOCITY</type>
        <p_gain>0.5</p_gain>
        <i_gain>0</i_gain>
        <d_gain>0</d_gain>
        <i_max>0</i_max>
        <i_min>0</i_min>
        <cmd_max>2.0</cmd_max>
        <cmd_min>0.0</cmd_min>
        <jointName>rotor_puller_joint</jointName>
      </control> -->
      <!-- <control channel="1">
        <multiplier>-1</multiplier>
        <offset>-0.5</offset>
        <type>POSITION</type>
        <p_gain>10.0</p_gain>
        <i_gain>0</i_gain>
        <d_gain>0</d_gain>
        <i_max>0</i_max>
        <i_min>0</i_min>
        <cmd_max>2.0</cmd_max>
        <cmd_min>-2.0</cmd_min>
        <jointName>left_elevon_joint</jointName>
      </control> -->
      <!-- <control channel="0">
        <multiplier>-1</multiplier>
        <offset>-0.5</offset>
        <type>POSITION</type>
        <p_gain>10.0</p_gain>
        <i_gain>0</i_gain>
        <d_gain>0</d_gain>
        <i_max>0</i_max>
        <i_min>0</i_min>
        <cmd_max>2.0</cmd_max>
        <cmd_min>-2.0</cmd_min>
        <jointName>right_elevon_joint</jointName>
      </control> -->
      <control channel="4">
        <type>VELOCITY</type>
        <offset>0</offset>
        <p_gain>0.20</p_gain>
        <i_gain>0</i_gain>
        <d_gain>0</d_gain>
        <i_max>0</i_max>
        <i_min>0</i_min>
        <cmd_max>2.5</cmd_max>
        <cmd_min>-2.5</cmd_min>
        <jointName>rotor_0_joint</jointName>
        <multiplier>838</multiplier>
        <!-- <multiplier>1500</multiplier> -->
        <controlVelocitySlowdownSim>1</controlVelocitySlowdownSim>
      </control>
      <control channel="5">
        <type>VELOCITY</type>
        <offset>0</offset>
        <p_gain>0.20</p_gain>
        <i_gain>0</i_gain>
        <d_gain>0</d_gain>
        <i_max>0</i_max>
        <i_min>0</i_min>
        <cmd_max>2.5</cmd_max>
        <cmd_min>-2.5</cmd_min>
        <jointName>rotor_1_joint</jointName>
        <multiplier>838</multiplier>
        <controlVelocitySlowdownSim>1</controlVelocitySlowdownSim>
      </control>
      <control channel="6">
        <type>VELOCITY</type>
        <offset>0</offset>
        <p_gain>0.20</p_gain>
        <i_gain>0</i_gain>
        <d_gain>0</d_gain>
        <i_max>0</i_max>
        <i_min>0</i_min>
        <cmd_max>2.5</cmd_max>
        <cmd_min>-2.5</cmd_min>
        <jointName>rotor_2_joint</jointName>
        <multiplier>-838</multiplier>
        <controlVelocitySlowdownSim>1</controlVelocitySlowdownSim>
      </control>
      <control channel="7">
        <type>VELOCITY</type>
        <offset>0</offset>
        <p_gain>0.20</p_gain>
        <i_gain>0</i_gain>
        <d_gain>0</d_gain>
        <i_max>0</i_max>
        <i_min>0</i_min>
        <cmd_max>2.5</cmd_max>
        <cmd_min>-2.5</cmd_min>
        <jointName>rotor_3_joint</jointName>
        <multiplier>-838</multiplier>
        <controlVelocitySlowdownSim>1</controlVelocitySlowdownSim>
      </control>
    </plugin>

  </model>
</sdf>
