<?xml version="1.0" encoding="utf-8"?>
<!-- This URDF was automatically created by SolidWorks to URDF Exporter! Originally created by Stephen Brawner (brawner@gmail.com) 
     Commit Version: 1.5.1-0-g916b5db  Build Version: 1.5.7152.31018
     For more information, please see http://wiki.ros.org/sw_urdf_exporter -->
<robot
  name="h_frame_tilt">
  <link
    name="base_link">
    <inertial>
      <origin
        xyz="-0.034153 -1.2818E-17 0.0037947"
        rpy="0 0 0" />
      <mass
        value="1.6105" />
      <inertia
        ixx="0.13199"
        ixy="-6.142E-18"
        ixz="0.00024729"
        iyy="0.077457"
        iyz="7.4254E-19"
        izz="0.2093" />
    </inertial>
    <visual>
      <origin
        xyz="0 0 0"
        rpy="0 0 0" />
      <geometry>
        <mesh
          filename="package://h_frame_tilt/meshes/base_link.STL" />
      </geometry>
      <material
        name="">
        <color
          rgba="1 1 1 1" />
      </material>
    </visual>
    <collision>
      <origin
        xyz="0 0 0"
        rpy="0 0 0" />
      <geometry>
        <mesh
          filename="package://h_frame_tilt/meshes/base_link.STL" />
      </geometry>
    </collision>
  </link>
  <link
    name="motor_0">
    <inertial>
      <origin
        xyz="0 5.5511E-17 0.048702"
        rpy="0 0 0" />
      <mass
        value="0.069653" />
      <inertia
        ixx="2.7086E-05"
        ixy="-5.5282E-22"
        ixz="4.1684E-22"
        iyy="1.7498E-05"
        iyz="-7.4714E-21"
        izz="1.2525E-05" />
    </inertial>
    <visual>
      <origin
        xyz="0 0 0"
        rpy="0 0 0" />
      <geometry>
        <mesh
          filename="package://h_frame_tilt/meshes/motor_0.STL" />
      </geometry>
      <material
        name="">
        <color
          rgba="0.65098 0.61961 0.58824 1" />
      </material>
    </visual>
    <collision>
      <origin
        xyz="0 0 0"
        rpy="0 0 0" />
      <geometry>
        <mesh
          filename="package://h_frame_tilt/meshes/motor_0.STL" />
      </geometry>
    </collision>
  </link>
  <joint
    name="motor_0_joint"
    type="revolute">
    <origin
      xyz="0.435 -0.325 0.005"
      rpy="0 0 0" />
    <parent
      link="base_link" />
    <child
      link="motor_0" />
    <axis
      xyz="0 1 0" />
    <limit
      lower="-0.017453"
      upper="1.5708"
      effort="0"
      velocity="0" />
  </joint>
  <link
    name="rotor_0">
    <inertial>
      <origin
        xyz="-7.2818E-09 -6.7605E-09 0.01856"
        rpy="0 0 0" />
      <mass
        value="0.067291" />
      <inertia
        ixx="0.0014406"
        ixy="-8.148E-05"
        ixz="1.1993E-12"
        iyy="1.3241E-05"
        iyz="9.4413E-13"
        izz="0.0014525" />
    </inertial>
    <visual>
      <origin
        xyz="0 0 0"
        rpy="0 0 0" />
      <geometry>
        <mesh
          filename="package://h_frame_tilt/meshes/rotor_0.STL" />
      </geometry>
      <material
        name="">
        <color
          rgba="1 1 1 1" />
      </material>
    </visual>
    <collision>
      <origin
        xyz="0 0 0"
        rpy="0 0 0" />
      <geometry>
        <mesh
          filename="package://h_frame_tilt/meshes/rotor_0.STL" />
      </geometry>
    </collision>
  </link>
  <joint
    name="rotor_0_joint"
    type="continuous">
    <origin
      xyz="0 0 0.047"
      rpy="0 0 0" />
    <parent
      link="motor_0" />
    <child
      link="rotor_0" />
    <axis
      xyz="0 0 1" />
  </joint>
  <link
    name="rotor_1">
    <inertial>
      <origin
        xyz="-6.5349E-09 -6.908E-09 0.015147"
        rpy="0 0 0" />
      <mass
        value="0.067291" />
      <inertia
        ixx="0.0014403"
        ixy="8.41E-05"
        ixz="1.0874E-12"
        iyy="1.3545E-05"
        iyz="1.0294E-12"
        izz="0.0014525" />
    </inertial>
    <visual>
      <origin
        xyz="0 0 0"
        rpy="0 0 0" />
      <geometry>
        <mesh
          filename="package://h_frame_tilt/meshes/rotor_1.STL" />
      </geometry>
      <material
        name="">
        <color
          rgba="1 1 1 1" />
      </material>
    </visual>
    <collision>
      <origin
        xyz="0 0 0"
        rpy="0 0 0" />
      <geometry>
        <mesh
          filename="package://h_frame_tilt/meshes/rotor_1.STL" />
      </geometry>
    </collision>
  </link>
  <joint
    name="rotor_1_joint"
    type="continuous">
    <origin
      xyz="-0.435 0.325 0.053413"
      rpy="0 0 0" />
    <parent
      link="base_link" />
    <child
      link="rotor_1" />
    <axis
      xyz="0 0 1" />
  </joint>
  <link
    name="motor_2">
    <inertial>
      <origin
        xyz="0 5.5511E-17 0.048702"
        rpy="0 0 0" />
      <mass
        value="0.069653" />
      <inertia
        ixx="2.7086E-05"
        ixy="-5.5793E-22"
        ixz="4.1248E-22"
        iyy="1.7498E-05"
        iyz="-6.6645E-21"
        izz="1.2525E-05" />
    </inertial>
    <visual>
      <origin
        xyz="0 0 0"
        rpy="0 0 0" />
      <geometry>
        <mesh
          filename="package://h_frame_tilt/meshes/motor_2.STL" />
      </geometry>
      <material
        name="">
        <color
          rgba="0.65098 0.61961 0.58824 1" />
      </material>
    </visual>
    <collision>
      <origin
        xyz="0 0 0"
        rpy="0 0 0" />
      <geometry>
        <mesh
          filename="package://h_frame_tilt/meshes/motor_2.STL" />
      </geometry>
    </collision>
  </link>
  <joint
    name="motor_2_joint"
    type="revolute">
    <origin
      xyz="0.435 0.325 0.005"
      rpy="0 0 0" />
    <parent
      link="base_link" />
    <child
      link="motor_2" />
    <axis
      xyz="0 1 0" />
    <limit
      lower="-0.017453"
      upper="1.5708"
      effort="0"
      velocity="0" />
  </joint>
  <link
    name="rotor_2">
    <inertial>
      <origin
        xyz="-2.2135E-09 -3.5357E-08 0.01856"
        rpy="0 0 0" />
      <mass
        value="0.067291" />
      <inertia
        ixx="0.0014451"
        ixy="1.4273E-05"
        ixz="6.5469E-13"
        iyy="8.7466E-06"
        iyz="3.5489E-12"
        izz="0.0014525" />
    </inertial>
    <visual>
      <origin
        xyz="0 0 0"
        rpy="0 0 0" />
      <geometry>
        <mesh
          filename="package://h_frame_tilt/meshes/rotor_2.STL" />
      </geometry>
      <material
        name="">
        <color
          rgba="1 1 1 1" />
      </material>
    </visual>
    <collision>
      <origin
        xyz="0 0 0"
        rpy="0 0 0" />
      <geometry>
        <mesh
          filename="package://h_frame_tilt/meshes/rotor_2.STL" />
      </geometry>
    </collision>
  </link>
  <joint
    name="rotor_2_joint"
    type="continuous">
    <origin
      xyz="0 0 0.047"
      rpy="0 0 0" />
    <parent
      link="motor_2" />
    <child
      link="rotor_2" />
    <axis
      xyz="0 0 1" />
  </joint>
  <link
    name="rotor_3">
    <inertial>
      <origin
        xyz="7.2715E-09 -7.1476E-09 0.015147"
        rpy="0 0 0" />
      <mass
        value="0.067296" />
      <inertia
        ixx="0.0014451"
        ixy="-1.9205E-05"
        ixz="-1.1812E-12"
        iyy="8.8623E-06"
        iyz="1.05E-12"
        izz="0.0014526" />
    </inertial>
    <visual>
      <origin
        xyz="0 0 0"
        rpy="0 0 0" />
      <geometry>
        <mesh
          filename="package://h_frame_tilt/meshes/rotor_3.STL" />
      </geometry>
      <material
        name="">
        <color
          rgba="1 1 1 1" />
      </material>
    </visual>
    <collision>
      <origin
        xyz="0 0 0"
        rpy="0 0 0" />
      <geometry>
        <mesh
          filename="package://h_frame_tilt/meshes/rotor_3.STL" />
      </geometry>
    </collision>
  </link>
  <joint
    name="rotor_3_joint"
    type="continuous">
    <origin
      xyz="-0.435 -0.325 0.053413"
      rpy="0 0 0" />
    <parent
      link="base_link" />
    <child
      link="rotor_3" />
    <axis
      xyz="0 0 1" />
  </joint>
</robot>